      <?xml version="1.0" ?>
      <robot name="robot1_xacro" xmlns:controller="http://playerstage.sourceforge.net/gazebo/xmlschema/#controller" xmlns:interface="http://playerstage.sourceforge.net/gazebo/xmlschema/#interface" xmlns:sensor="http://playerstage.sourceforge.net/gazebo/xmlschema/#sensor">
       <link name="base_footprint">
      <visual>
      <geometry>
      <box size="0.001 0.001 0.001"/>
      </geometry>
      <origin rpy="0 0 0" xyz="0 0 0"/>
      </visual>
      <inertial>
      <mass value="0.0001"/>
      <inertia ixx="1.0" ixy="0.0" ixz="0.0" iyy="1.0" iyz="0.0" izz="1.0"/>
      </inertial>
       </link>
       <gazebo reference="base_footprint">
      <material>Gazebo/Green</material>
      <turnGravityOff>false</turnGravityOff>
       </gazebo>
       <joint name="base_footprint_joint" type="fixed">
      <origin xyz="0 0 0"/>
      <parent link="base_footprint"/>
      <child link="base_link"/>
       </joint>
       <link name="base_link">
      <visual>
      <geometry>
      <box size="0.2 .3 .1"/>
      </geometry>
      <origin rpy="0 0 1.54" xyz="0 0 0.05"/>
      <material name="white">
      <color rgba="1 1 1 1"/>
      </material>
      </visual>
      <collision>
      <geometry>
      <box size="0.2 .3 0.1"/>
      </geometry>
      </collision>
      <inertial>
      <mass value="10"/>
      <inertia ixx="1.0" ixy="0.0" ixz="0.0" iyy="1.0" iyz="0.0" izz="1.0"/>
      </inertial>
       </link>
       <link name="wheel_1">
      <visual>
      <geometry>
      <cylinder length="0.05" radius="0.05"/>
      </geometry>
      <origin rpy="0 0 0" xyz="0 0 0"/>
      <material name="black">
      <color rgba="0 0 0 1"/>
      </material>
      </visual>
      <collision>
      <geometry>
      <cylinder length="0.05" radius="0.05"/>
      </geometry>
      </collision>
      <inertial>
      <mass value="1"/>
      <inertia ixx="1.0" ixy="0.0" ixz="0.0" iyy="1.0" iyz="0.0" izz="1.0"/>
      </inertial>
       </link>
       <link name="wheel_2">
      <visual>
      <geometry>
      <cylinder length="0.05" radius="0.05"/>
      </geometry>
      <origin rpy="0 0 0" xyz="0 0 0"/>
      <material name="black"/>
      </visual>
      <collision>
      <geometry>
      <cylinder length="0.05" radius="0.05"/>
      </geometry>
      </collision>
      <inertial>
      <mass value="1"/>
      <inertia ixx="1.0" ixy="0.0" ixz="0.0" iyy="1.0" iyz="0.0" izz="1.0"/>
      </inertial>
       </link>
       <link name="wheel_3">
      <visual>
      <geometry>
      <cylinder length="0.05" radius="0.05"/>
      </geometry>
      <origin rpy="0 0 0" xyz="0 0 0"/>
      <material name="black"/>
      </visual>
      <collision>
      <geometry>
      <cylinder length="0.05" radius="0.05"/>
      </geometry>
      </collision>
      <inertial>
      <mass value="1"/>
      <inertia ixx="1.0" ixy="0.0" ixz="0.0" iyy="1.0" iyz="0.0" izz="1.0"/>
      </inertial>
       </link>
       <link name="wheel_4">
      <visual>
      <geometry>
      <cylinder length="0.05" radius="0.05"/>
      </geometry>
      <origin rpy="0 0 0" xyz="0 0 0"/>
      <material name="black"/>
      </visual>
      <collision>
      <geometry>
      <cylinder length="0.05" radius="0.05"/>
      </geometry>
      </collision>
      <inertial>
      <mass value="1"/>
      <inertia ixx="1.0" ixy="0.0" ixz="0.0" iyy="1.0" iyz="0.0" izz="1.0"/>
      </inertial>
       </link>
       <joint name="base_to_wheel1" type="continuous">
      <parent link="base_link"/>
      <child link="wheel_1"/>
      <origin rpy="1.5707 0 0" xyz="0.1 0.15 0"/>
      <axis xyz="0 0 1"/>
       </joint>
       <joint name="base_to_wheel2" type="continuous">
      <axis xyz="0 0 1"/>
      <anchor xyz="0 0 0"/>
      <limit effort="100" velocity="100"/>
      <parent link="base_link"/>
      <child link="wheel_2"/>
      <origin rpy="1.5707 0 0" xyz="-0.1 0.15 0"/>
       </joint>
       <joint name="base_to_wheel3" type="continuous">
      <parent link="base_link"/>
      <axis xyz="0 0 1"/>
      <child link="wheel_3"/>
      <origin rpy="1.5707 0 0" xyz="0.1 -0.15 0"/>
       </joint>
       <joint name="base_to_wheel4" type="continuous">
      <parent link="base_link"/>
      <axis xyz="0 0 1"/>
      <child link="wheel_4"/>
      <origin rpy="1.5707 0 0" xyz="-0.1 -0.15 0"/>
       </joint>
      </robot>